Workbook
Name AttrUnique: TypeSystem!$E$1
Name AttrQualifier: TypeSystem!$C$1
Name AttrLocLang: TypeSystem!$I$1
Name AttrLocalized: TypeSystem!$H$1
Name AttrTypeCode: TypeSystem!$F$1
Name AttrDisplayedNameRef: TypeSystem!$J$1
Name AttrName: TypeSystem!$D$1
Name TypeName: TypeSystem!$B$1
Name AttrTypeItemType: TypeSystem!$G$1
Name AttrOptional: TypeSystem!$E$1
Name TypeCode: TypeSystem!$A$1
Name HeaderTypeCode: HeaderPrompt!$A$1

Sheet TypeTemplate
A1: (Select Property)
A2: =IFERROR(VLOOKUP(A$1,HeaderPrompt!B:C,2,FALSE),"") | B2: =IFERROR(VLOOKUP(B$1,HeaderPrompt!B:C,2,FALSE),"") | C2: =IFERROR(VLOOKUP(C$1,HeaderPrompt!B:C,2,FALSE),"") | D2: =IFERROR(VLOOKUP(D$1,HeaderPrompt!B:C,2,FALSE),"") | E2: =IFERROR(VLOOKUP(E$1,HeaderPrompt!B:C,2,FALSE),"") | F2: =IFERROR(VLOOKUP(F$1,HeaderPrompt!B:C,2,FALSE),"") | G2: =IFERROR(VLOOKUP(G$1,HeaderPrompt!B:C,2,FALSE),"") | H2: =IFERROR(VLOOKUP(H$1,HeaderPrompt!B:C,2,FALSE),"") | ... KN2: =IFERROR(VLOOKUP(KN$1,HeaderPrompt!B:C,2,FALSE),"")

Sheet TypeSystem
A1: TypeCode | B1: TypeName | C1: AttrQualifier | D1: AttrName | E1: AttrOptional | F1: AttrTypeCode | G1: AttrTypeItemType | H1: AttrLocalized | I1: AttrLocLang | J1: AttrDisplayedName | K1: AttrUnique | L1: ReferenceFormat
A2: {Product} | B2: Product | C2: simpleBannerComponents | D2: Simple Banner Components | E2: true | F2: SimpleBannerComponentsForProductsimpleBannerComponentsColl | G2: Product | H2: false | J2: {Simple Banner Components+} | K2: false | L2: SimpleBannerComponent.uid:CatalogVersion.version:Catalog.id
A3: {Product} | B3: Product | C3: offlineDate | D3: Online to | E3: true | F3: java.util.Date | G3: Product | H3: false | J3: {Online to} | K3: false | L3: dd.MM.yyyy HH:mm:ss
A4: {Product} | B4: Product | C4: packagingSize | E4: true | F4: java.lang.String | G4: Product | H4: false | J4: {packagingSize} | K4: false
A5: {Product} | B5: Product | C5: comments | D5: Comments | E5: true | F5: CommentItemRelationcommentsColl | G5: Item | H5: false | J5: {Comments+} | K5: false | L5: Comment.code
A6: {Product} | B6: Product | C6: remarks | D6: Remarks | E6: true | F6: localized:java.lang.String | G6: Product | H6: true | I6: {en},{de},{ja},{zh} | J6: {Remarks[en]},{Remarks[de]},{Remarks[ja]},{Remarks[zh]} | K6: false
A7: {Product} | B7: Product | C7: productType | E7: true | F7: ProductType | G7: Product | H7: false | J7: {productType} | K7: false
A8: {Product} | B8: Product | C8: thumbnail | D8: Thumbnail | E8: true | F8: Media | G8: Product | H8: false | J8: {Thumbnail} | K8: false | L8: filePath:code:catalog:version:folder
A9: {Product} | B9: Product | C9: length | E9: true | F9: java.lang.String | G9: Product | H9: false | J9: {length} | K9: false
A10: {Product} | B10: Product | C10: linkComponents | D10: Link Components | E10: true | F10: CmsLinkComponentsForProductlinkComponentsColl | G10: Product | H10: false | J10: {Link Components+} | K10: false | L10: CMSLinkComponent.uid:CatalogVersion.version:Catalog.id
A11: {Product} | B11: Product | C11: creationtime | D11: Time created | E11: true | F11: java.util.Date | G11: Item | H11: false | J11: {Time created=} | K11: false | L11: dd.MM.yyyy HH:mm:ss
A12: {Product} | B12: Product | C12: endLineNumber | D12: Line number in XML (end) | E12: true | F12: java.lang.Integer | G12: Product | H12: false | J12: {Line number in XML (end)} | K12: false
A13: {Product} | B13: Product | C13: Europe1PriceFactory_PTG | D13: Tax Class | E13: true | F13: ProductTaxGroup | G13: Product | H13: false | J13: {Tax Class} | K13: false
A14: {Product} | B14: Product | C14: thumbnails | D14: Thumbnails | E14: true | F14: MediaCollection | G14: Product | H14: false | J14: {Thumbnails+} | K14: false | L14: filePath:code:catalog:version:folder
A15: {Product} | B15: Product | C15: packagingType | E15: true | F15: java.lang.String | G15: Product | H15: false | J15: {packagingType} | K15: false
A16: {Product} | B16: Product | C16: deliveryTime | D16: Delivery time | E16: true | F16: java.lang.Double | G16: Product | H16: false | J16: {Delivery time} | K16: false
A17: {Product} | B17: Product | C17: bucketSize | E17: true | F17: java.lang.String | G17: Product | H17: false | J17: {bucketSize} | K17: false
A18: {Product} | B18: Product | C18: sequenceId | D18: Sequence ID | E18: true | F18: java.lang.Long | G18: Product | H18: false | J18: {Sequence ID} | K18: false
A19: {Product} | B19: Product | C19: productListComponents | D19: Product List Components | E19: true | F19: ProductsForProductListComponentproductListComponentsColl | G19: Product | H19: false | J19: {Product List Components+} | K19: false | L19: ProductListComponent.uid:CatalogVersion.version:Catalog.id
A20: {Product} | B20: Product | C20: unit | D20: Sales unit | E20: true | F20: Unit | G20: Product | H20: false | J20: {Sales unit} | K20: false | L20: Unit.code
A21: {Product} | B21: Product | C21: engineMake | E21: true | F21: java.lang.String | G21: Product | H21: false | J21: {engineMake} | K21: false
A22: {Product} | B22: Product | C22: loaderReachMaxHeight | E22: true | F22: java.lang.String | G22: Product | H22: false | J22: {loaderReachMaxHeight} | K22: false
A23: {Product} | B23: Product | C23: armSize | E23: true | F23: java.lang.String | G23: Product | H23: false | J23: {armSize} | K23: false
A24: {Product} | B24: Product | C24: reviewCount | D24: Persisted Total Reviews | E24: true | F24: java.lang.Integer | G24: Product | H24: false | J24: {Persisted Total Reviews} | K24: false
A25: {Product} | B25: Product | C25: sapBlocked | D25: Blocked | E25: true | F25: java.lang.Boolean | G25: Product | H25: false | J25: {Blocked} | K25: false
A26: {Product} | B26: Product | C26: machineType | E26: true | F26: MachineType | G26: Product | H26: false | J26: {machineType} | K26: false
A27: {Product} | B27: Product | C27: materialDensity | E27: true | F27: java.lang.String | G27: Product | H27: false | J27: {materialDensity} | K27: false
A28: {Product} | B28: Product | C28: code | D28: Article Number | E28: false | F28: java.lang.String | G28: Product | H28: false | J28: {Article Number*^} | K28: true
A29: {Product} | B29: Product | C29: backhoeShovel | E29: true | F29: java.lang.String | G29: Product | H29: false | J29: {backhoeShovel} | K29: false
A30: {Product} | B30: Product | C30: sapEAN | D30: EAN | E30: true | F30: java.lang.String | G30: Product | H30: false | J30: {EAN[sapEAN]} | K30: false
A31: {Product} | B31: Product | C31: pileDensityUpto | E31: true | F31: java.lang.String | G31: Product | H31: false | J31: {pileDensityUpto} | K31: false
A32: {Product} | B32: Product | C32: ean | D32: EAN | E32: true | F32: java.lang.String | G32: Product | H32: false | J32: {EAN[ean]} | K32: false
A33: {Product} | B33: Product | C33: Europe1PriceFactory_PDG | D33: Discount Class | E33: true | F33: ProductDiscountGroup | G33: Product | H33: false | J33: {Discount Class} | K33: false
A34: {Product} | B34: Product | C34: variantType | D34: Product variants type | E34: true | F34: VariantType | G34: Product | H34: false | J34: {Product variants type} | K34: false | L34: VariantType.code
A35: {Product} | B35: Product | C35: height | E35: true | F35: java.lang.String | G35: Product | H35: false | J35: {height} | K35: false
A36: {Product} | B36: Product | C36: manufacturerTypeDescription | D36: Manufacturer description | E36: true | F36: localized:java.lang.String | G36: Product | H36: true | I36: {en},{de},{ja},{zh} | J36: {Manufacturer description[en]},{Manufacturer description[de]},{Manufacturer description[ja]},{Manufacturer description[zh]} | K36: false
A37: {Product} | B37: Product | C37: loadOverHeight | E37: true | F37: java.lang.String | G37: Product | H37: false | J37: {loadOverHeight} | K37: false
A38: {Product} | B38: Product | C38: reviewRating | D38: Persisted Average Rating | E38: true | F38: java.lang.Double | G38: Product | H38: false | J38: {Persisted Average Rating} | K38: false
A39: {Product} | B39: Product | C39: sapBaseUnitConversion | D39: Base Unit Conversion | E39: true | F39: java.lang.Double | G39: Product | H39: false | J39: {Base Unit Conversion} | K39: false
A40: {Product} | B40: Product | C40: priceQuantity | D40: Price quantity | E40: true | F40: java.lang.Double | G40: Product | H40: false | J40: {Price quantity} | K40: false
...

Sheet ClassificationTypeSystem
A1: FullName | B1: ClassificationSystem | C1: ClassificationVersion | D1: ClassificationClass | E1: ClassificationAttribute | F1: AttrLocalized | G1: AttrLocLang | H1: IsMandatory

Sheet HeaderPrompt
A1: HeaderTypeCode | B1: HeaderAttrDisplayedName | C1: HeaderReferenceFormat
A2: Product | B2: Alternative ID
A3: Product | B3: Approval
A4: Product | B4: Article Number*^
A5: Product | B5: Article order
A6: Product | B6: Base Unit Conversion
A7: Product | B7: Blocked
A8: Product | B8: Blocked Date | C8: dd.MM.yyyy HH:mm:ss
A9: Product | B9: Carousel Components+ | C9: ProductCarouselComponent.uid:CatalogVersion.version:Catalog.id
A10: Product | B10: Catalog version*^ | C10: CatalogVersion.version:Catalog.id
A11: Product | B11: Comments+ | C11: Comment.code
A12: Product | B12: Configurable
A13: Product | B13: Content unit | C13: Unit.code
A14: Product | B14: Delivery Modes+ | C14: DeliveryMode.code
A15: Product | B15: Delivery time
A16: Product | B16: Description[zh]
A17: Product | B17: Description[de]
A18: Product | B18: Description[ja]
A19: Product | B19: Description[en]
A20: Product | B20: Details+ | C20: filePath:code:catalog:version:folder
A21: Product | B21: Discount Class
A22: Product | B22: EAN[sapEAN]
A23: Product | B23: EAN[ean]
A24: Product | B24: ERP group buyer
A25: Product | B25: ERP group supplier
A26: Product | B26: Gallery Images+ | C26: MediaContainer.qualifier:CatalogVersion.version:Catalog.id
A27: Product | B27: Identifier[de]
A28: Product | B28: Identifier[ja]
A29: Product | B29: Identifier[en]
A30: Product | B30: Identifier[zh]
A31: Product | B31: Image | C31: filePath:code:catalog:version:folder
A32: Product | B32: Keywords[de]+ | C32: Keyword.keyword:CatalogVersion.version:Catalog.id:Language.isocode
A33: Product | B33: Keywords[zh]+ | C33: Keyword.keyword:CatalogVersion.version:Catalog.id:Language.isocode
A34: Product | B34: Keywords[en]+ | C34: Keyword.keyword:CatalogVersion.version:Catalog.id:Language.isocode
A35: Product | B35: Keywords[ja]+ | C35: Keyword.keyword:CatalogVersion.version:Catalog.id:Language.isocode
A36: Product | B36: Line number in XML (end)
A37: Product | B37: Line number in XML (start)
A38: Product | B38: Link Components+ | C38: CMSLinkComponent.uid:CatalogVersion.version:Catalog.id
A39: Product | B39: Logos+ | C39: filePath:code:catalog:version:folder
A40: Product | B40: Manufacturer
...

Sheet products
A1: Article Number | B1: Description | C1: Identifier | D1: Keywords | E1: Price | F1: Price quantity | G1: Prices+ | H1: Sold individually | I1: height | J1: length | K1: operatingWeight | L1: productType | M1: weight | N1: width
A2: YD40000702 | C2: COVER | E2: 0.0 INR:N::1 EA:: | F2: 1.0 | G2: 0.0 INR:N::1 EA:: | H2: true | L2: SpareParts
A3: YD00008723 | C3: SEAL;RUBBER | F3: 1.0 | H3: true | L3: SpareParts
A4: YD00004167 | C4: * ROLLER | F4: 1.0 | H4: true | L4: SpareParts
A5: YD00001375 | C5: BUSHING;RUBBER | F5: 1.0 | H5: true | L5: SpareParts
A6: YD00010097 | C6: INSULATOR | F6: 1.0 | H6: true | L6: SpareParts
A7: YD00003341 | C7: HOSE | F7: 1.0 | H7: true | L7: SpareParts
A8: YD00000772 | C8: HOSE | E8: 5235.66 INR:N::1 EA:: | F8: 1.0 | G8: 5235.66 INR:N::1 EA:: | H8: true | L8: SpareParts
A9: YD00002131 | C9: SEAL;RUBBER | F9: 1.0 | H9: true | L9: SpareParts
A10: YD00011148 | C10: INSULATOR | F10: 1.0 | H10: true | L10: SpareParts
A11: YD00006406 | C11: PLATE | F11: 1.0 | H11: true | L11: SpareParts
A12: YD40002054 | C12: PIPE | E12: 4761.3 INR:N::1 EA:: | F12: 1.0 | G12: 4761.3 INR:N::1 EA:: | H12: true | L12: SpareParts
A13: YD00008711 | C13: SEAL;RUBBER | E13: 1667.34 INR:N::1 EA:: | F13: 1.0 | G13: 1667.34 INR:N::1 EA:: | H13: true | L13: SpareParts
A14: YD00003427 | C14: BRACKET | F14: 1.0 | H14: true | L14: SpareParts
A15: YD00007645 | C15: NAME-PLATE | E15: 743.4 INR:N::1 EA:: | F15: 1.0 | G15: 743.4 INR:N::1 EA:: | H15: true | L15: SpareParts
A16: YD00005399 | C16: COVER | F16: 1.0 | H16: true | L16: SpareParts
A17: YD00003282 | C17: HOSE | E17: 4089.88 INR:N::1 EA:: | F17: 1.0 | G17: 4089.88 INR:N::1 EA:: | H17: true | L17: SpareParts
A18: YD60003392 | C18: PLATE | E18: 0.0 INR:N::1 EA:: | F18: 1.0 | G18: 0.0 INR:N::1 EA:: | H18: true | L18: SpareParts
A19: YD00005162 | B19: Engine Fan Belt | C19: BELT FAN | E19: 4030.88 INR:N::1 EA:: | F19: 1.0 | G19: 4030.88 INR:N::1 EA:: | H19: true | K19: 1 | L19: SpareParts
A20: YD00001182 | C20: SEAL;RUBBER | F20: 1.0 | H20: true | L20: SpareParts
A21: YD40002594 | C21: STOPPER | F21: 1.0 | H21: true | L21: SpareParts
A22: YD00004027 | C22: *HOSE | F22: 1.0 | H22: true | L22: SpareParts
A23: YD40000549 | C23: BRACKET | F23: 1.0 | H23: true | L23: SpareParts
A24: YD00008868 | C24: * SECTION (BOOM) | E24: 89604.48 INR:N::1 EA:: | F24: 1.0 | G24: 89604.48 INR:N::1 EA:: | H24: true | L24: SpareParts
A25: YD00003278 | C25: BRACKET | F25: 1.0 | H25: true | L25: SpareParts
A26: YD00003088 | C26: SEAL;RUBBER | F26: 1.0 | H26: true | L26: SpareParts
A27: YD00006007 | C27: HOSE;COOLER | E27: 0.0 INR:N::1 EA:: | F27: 1.0 | G27: 0.0 INR:N::1 EA:: | H27: true | L27: SpareParts
A28: YD00007887 | B28: B30_Attachment | C28: VALVE | E28: 7232.22 INR:N::1 EA:: | F28: 1.0 | G28: 7232.22 INR:N::1 EA:: | H28: true | I28: 81 | J28: 81 | K28: 1 | L28: SpareParts | M28: 1.00 | N28: 36
A29: YD00008053 | C29: INSULATOR | F29: 1.0 | H29: true | L29: SpareParts
A30: YD00008883 | B30: Applicable Cylinder Part No YD00006748 | C30: BOOM CYLINDER SEAL KIT | E30: 21074.8 INR:N::1 EA:: | F30: 1.0 | G30: 21074.8 INR:N::1 EA:: | H30: true | I30: 150 | J30: 150 | K30: 1 | L30: SpareParts | M30: 0.20 | N30: 40
A31: YD00007975 | C31: * LINK | E31: 0.0 INR:N::1 EA:: | F31: 1.0 | G31: 0.0 INR:N::1 EA:: | H31: true | L31: SpareParts
A32: YD60003622 | C32: ASSY;HOSE | E32: 2017.8 INR:N::1 EA:: | F32: 1.0 | G32: 2017.8 INR:N::1 EA:: | H32: true | L32: SpareParts
A33: YD00004592 | C33: HOSE | F33: 1.0 | H33: true | L33: SpareParts
A34: YD00000877 | C34: COVER;REAR | E34: 20816.38 INR:N::1 EA:: | F34: 1.0 | G34: 20816.38 INR:N::1 EA:: | H34: true | L34: SpareParts
A35: YD60005326 | C35: ASSY;HOSE | E35: 2456.76 INR:N::1 EA:: | F35: 1.0 | G35: 2456.76 INR:N::1 EA:: | H35: true | L35: SpareParts
A36: YD00000517 | C36: * SECTION (BLADE) | F36: 1.0 | H36: true | L36: SpareParts
A37: YD00005513 | C37: NUT | F37: 1.0 | H37: true | L37: SpareParts
A38: YD00002130 | C38: SEAL;RUBBER | F38: 1.0 | H38: true | L38: SpareParts
A39: YD40001465 | C39: BRACKET | E39: 1877.38 INR:N::1 EA:: | F39: 1.0 | G39: 1877.38 INR:N::1 EA:: | H39: true | L39: SpareParts
A40: YD40000371 | C40: FRAME;MAIN | E40: 1280275.22 INR:N::1 EA:: | F40: 1.0 | G40: 1280275.22 INR:N::1 EA:: | H40: true | L40: SpareParts
...
